Workbook

Sheet Сводная
A1: Бренд | B1: Предмет | C1: Артикул | D1: Артикул WB | E1: Баркод | F1: Размер | G1: Электросталь | H1: Краснодар | I1: Невинномысск | J1: Шушары | K1: Рязань | L1: Пенза | M1: Сарапул | N1: Волгоград | O1: Новосемейкино Самара | P1: Владимир | Q1: Тула | R1: ЕКБ Перспективная | S1: Коледино | T1: Котовск | U1: Цена | V1: Итого шт | W1: Итого ₽
A2: Infinity Story | B2: Блузки | C2: БЛУЗКАКЕЙП/Белый | D2: 890424550 | E2: 2049705238712 | F2: XS-S | G2: 1 | J2: 2 | O2: 1 | Q2: 2 | U2: 2390 | V2: =SUM(G2:T2) -> 6 | W2: =IF(U2="","",U2*V2) -> 14340
A3: Infinity Story | B3: Блузки | C3: БЛУЗКАКЕЙП/Белый | D3: 890424550 | E3: 2049705238736 | F3: M-L | I3: 1 | K3: 1 | P3: 1 | U3: 2390 | V3: =SUM(G3:T3) -> 3 | W3: =IF(U3="","",U3*V3) -> 7170
A4: Infinity Story | B4: Блузки | C4: БЛУЗКАКЕЙП/Белый | D4: 890424550 | E4: 2049705238729 | F4: XL-XXL | K4: 1 | Q4: 1 | U4: 2390 | V4: =SUM(G4:T4) -> 2 | W4: =IF(U4="","",U4*V4) -> 4780
A5: Infinity Story | B5: Блузки | C5: БЛУЗКАКЕЙП/Бордовый | D5: 890432709 | E5: 2049705310210 | F5: XS-S | G5: 2 | J5: 1 | Q5: 34 | T5: 1 | U5: 2390 | V5: =SUM(G5:T5) -> 38 | W5: =IF(U5="","",U5*V5) -> 90820
A6: Infinity Story | B6: Блузки | C6: БЛУЗКАКЕЙП/Бордовый | D6: 890432709 | E6: 2049705310197 | F6: M-L | I6: 2 | K6: 1 | M6: 1 | O6: 1 | P6: 2 | Q6: 9 | U6: 2390 | V6: =SUM(G6:T6) -> 16 | W6: =IF(U6="","",U6*V6) -> 38240
A7: Infinity Story | B7: Блузки | C7: БЛУЗКАКЕЙП/Бордовый | D7: 890432709 | E7: 2049705310203 | F7: XL-XXL | I7: 1 | J7: 1 | K7: 1 | M7: 1 | U7: 2390 | V7: =SUM(G7:T7) -> 4 | W7: =IF(U7="","",U7*V7) -> 9560
A8: Infinity Story | B8: Блузки | C8: КЕЙПВУАЛЬ/Черный | D8: 824672713 | E8: 2046448653932 | F8: ONE SIZE | P8: 1 | S8: 1 | U8: 2520 | V8: =SUM(G8:T8) -> 2 | W8: =IF(U8="","",U8*V8) -> 5040
A9: Infinity Story | B9: Блузки | C9: КЕЙПВУАЛЬ/Шоколадный | D9: 824664370 | E9: 2046448962607 | F9: ONE SIZE | G9: 1 | J9: 1 | K9: 6 | M9: 2 | N9: 1 | O9: 1 | U9: 2100 | V9: =SUM(G9:T9) -> 12 | W9: =IF(U9="","",U9*V9) -> 25200
A10: Infinity Story | B10: Блузки | C10: КЕЙПНАКИДКА/Белый | D10: 831403025 | E10: 2049108835723 | F10: ONE SIZE | J10: 2 | K10: 1 | L10: 1 | P10: 1 | R10: 1 | U10: 2950 | V10: =SUM(G10:T10) -> 6 | W10: =IF(U10="","",U10*V10) -> 17700
A11: Infinity Story | B11: Блузки | C11: КЕЙПНАКИДКА/Бордовый | D11: 831415374 | E11: 2049108959375 | F11: ONE SIZE | G11: 1 | K11: 2 | M11: 1 | O11: 1 | P11: 2 | Q11: 2 | R11: 1 | S11: 1 | U11: 2950 | V11: =SUM(G11:T11) -> 11 | W11: =IF(U11="","",U11*V11) -> 32450
A12: Infinity Story | B12: Блузки | C12: ЛОНГСЕТКА/бежевый | D12: 915548724 | E12: 2039739681219 | F12: M | O12: 1 | Q12: 5 | R12: 1 | U12: 1440 | V12: =SUM(G12:T12) -> 7 | W12: =IF(U12="","",U12*V12) -> 10080
A13: Infinity Story | B13: Блузки | C13: ЛОНГСЕТКА/бежевый | D13: 915548724 | E13: 2039739681202 | F13: L | H13: 1 | Q13: 14 | U13: 1440 | V13: =SUM(G13:T13) -> 15 | W13: =IF(U13="","",U13*V13) -> 21600
A14: Infinity Story | B14: Блузки | C14: ЛОНГСЕТКА/бежевый | D14: 915548724 | E14: 2039739681233 | F14: XL | G14: 2 | Q14: 2 | U14: 1440 | V14: =SUM(G14:T14) -> 4 | W14: =IF(U14="","",U14*V14) -> 5760
A15: Infinity Story | B15: Блузки | C15: ЛОНГСЕТКА/черный | D15: 915543532 | E15: 2039739638237 | F15: XS | Q15: 12 | U15: 1440 | V15: =SUM(G15:T15) -> 12 | W15: =IF(U15="","",U15*V15) -> 17280
A16: Infinity Story | B16: Блузки | C16: ЛОНГСЕТКА/черный | D16: 915543532 | E16: 2039739638244 | F16: S | K16: 1 | U16: 1440 | V16: =SUM(G16:T16) -> 1 | W16: =IF(U16="","",U16*V16) -> 1440
A17: Infinity Story | B17: Блузки | C17: ЛОНГСЕТКА/черный | D17: 915543532 | E17: 2039739638268 | F17: L | G17: 2 | U17: 1440 | V17: =SUM(G17:T17) -> 2 | W17: =IF(U17="","",U17*V17) -> 2880
A18: Infinity Story | B18: Блузки | C18: ЛОНГСЕТКА/черный | D18: 915543532 | E18: 2039739638275 | F18: XL | G18: 1 | H18: 1 | U18: 1440 | V18: =SUM(G18:T18) -> 2 | W18: =IF(U18="","",U18*V18) -> 2880
A19: Infinity Story | B19: Брюки | C19: БРЮКИПОЛОСКА/Бежевый | D19: 824584442 | E19: 2048742255379 | F19: M-L | J19: 1 | Q19: 1 | T19: 1 | U19: 2790 | V19: =SUM(G19:T19) -> 3 | W19: =IF(U19="","",U19*V19) -> 8370
A20: Infinity Story | B20: Брюки | C20: БРЮКИПОЛОСКА/Бежевый | D20: 824584442 | E20: 2048742255386 | F20: XL-XXL | G20: 1 | K20: 1 | Q20: 1 | U20: 2790 | V20: =SUM(G20:T20) -> 3 | W20: =IF(U20="","",U20*V20) -> 8370
A21: Infinity Story | B21: Брюки | C21: БРЮКИПОЛОСКА/Коричневый | D21: 824597933 | E21: 2048768718872 | F21: XS-S | G21: 1 | K21: 1 | U21: 2790 | V21: =SUM(G21:T21) -> 2 | W21: =IF(U21="","",U21*V21) -> 5580
A22: Infinity Story | B22: Брюки | C22: БРЮКИПОЛОСКА/Коричневый | D22: 824597933 | E22: 2048768718858 | F22: M-L | K22: 1 | M22: 1 | O22: 1 | U22: 2790 | V22: =SUM(G22:T22) -> 3 | W22: =IF(U22="","",U22*V22) -> 8370
A23: Infinity Story | B23: Брюки | C23: БРЮКИПОЛОСКА/Коричневый | D23: 824597933 | E23: 2048768718865 | F23: XL-XXL | J23: 1 | Q23: 1 | U23: 2790 | V23: =SUM(G23:T23) -> 2 | W23: =IF(U23="","",U23*V23) -> 5580
A24: Infinity Story | B24: Жилеты | C24: ЖИЛЕТКА/Бежевый | D24: 915700564 | E24: 2038591635361 | F24: XS | Q24: 1 | S24: 1 | U24: 1600 | V24: =SUM(G24:T24) -> 2 | W24: =IF(U24="","",U24*V24) -> 3200
A25: Infinity Story | B25: Жилеты | C25: ЖИЛЕТКА/Бежевый | D25: 915700564 | E25: 2038591635378 | F25: S | O25: 1 | U25: 1600 | V25: =SUM(G25:T25) -> 1 | W25: =IF(U25="","",U25*V25) -> 1600
A26: Infinity Story | B26: Жилеты | C26: ЖИЛЕТКА/Бежевый | D26: 915700564 | E26: 2038591635408 | F26: XL | R26: 1 | U26: 1600 | V26: =SUM(G26:T26) -> 1 | W26: =IF(U26="","",U26*V26) -> 1600
A27: Infinity Story | B27: Жилеты | C27: ЖИЛЕТКА/Темно-серый | D27: 915698461 | E27: 2041129314782 | F27: XS | P27: 1 | R27: 1 | U27: 1565 | V27: =SUM(G27:T27) -> 2 | W27: =IF(U27="","",U27*V27) -> 3130
A28: Infinity Story | B28: Жилеты | C28: ЖИЛЕТКА/Темно-серый | D28: 915698461 | E28: 2041129314768 | F28: S | Q28: 2 | R28: 1 | U28: 1565 | V28: =SUM(G28:T28) -> 3 | W28: =IF(U28="","",U28*V28) -> 4695
A29: Infinity Story | B29: Жилеты | C29: ЖИЛЕТКА/Темно-серый | D29: 915698461 | F29: M | J29: 1 | U29: 1565 | V29: =SUM(G29:T29) -> 1 | W29: =IF(U29="","",U29*V29) -> 1565
A30: Infinity Story | B30: Жилеты | C30: ЖИЛЕТКА/Черный | D30: 915688094 | E30: 2038590753301 | F30: XS | I30: 1 | Q30: 5 | U30: 1565 | V30: =SUM(G30:T30) -> 6 | W30: =IF(U30="","",U30*V30) -> 9390
A31: Infinity Story | B31: Жилеты | C31: ЖИЛЕТКА/Черный | D31: 915688094 | E31: 2038590753318 | F31: S | Q31: 7 | U31: 1565 | V31: =SUM(G31:T31) -> 7 | W31: =IF(U31="","",U31*V31) -> 10955
A32: Infinity Story | B32: Жилеты | C32: ЖИЛЕТКА/Черный | D32: 915688094 | E32: 2038590753325 | F32: M | K32: 1 | Q32: 2 | U32: 1565 | V32: =SUM(G32:T32) -> 3 | W32: =IF(U32="","",U32*V32) -> 4695
A33: Infinity Story | B33: Жилеты | C33: ЖИЛЕТКА/Черный | D33: 915688094 | E33: 2038590753332 | F33: L | K33: 1 | Q33: 6 | U33: 1565 | V33: =SUM(G33:T33) -> 7 | W33: =IF(U33="","",U33*V33) -> 10955
A34: Infinity Story | B34: Жилеты | C34: ЖИЛЕТКА/Черный | D34: 915688094 | E34: 2038590753349 | F34: XL | H34: 1 | Q34: 12 | U34: 1565 | V34: =SUM(G34:T34) -> 13 | W34: =IF(U34="","",U34*V34) -> 20345
A35: Infinity Story | B35: Жилеты | C35: ЖИЛЕТКА/Черный | D35: 915688094 | E35: 2039582201725 | F35: XXL | Q35: 11 | U35: 1565 | V35: =SUM(G35:T35) -> 11 | W35: =IF(U35="","",U35*V35) -> 17215
A36: Infinity Story | B36: Кардиганы | C36: КАРДИГАНДЛИН/бежевый | D36: 824413362 | E36: 2036852572578 | F36: XS-M | G36: 1 | Q36: 14 | U36: 1890 | V36: =SUM(G36:T36) -> 15 | W36: =IF(U36="","",U36*V36) -> 28350
A37: Infinity Story | B37: Кардиганы | C37: КАРДИГАНДЛИН/бежевый | D37: 824413362 | E37: 2038538739534 | F37: L-XXL | M37: 1 | Q37: 12 | U37: 1890 | V37: =SUM(G37:T37) -> 13 | W37: =IF(U37="","",U37*V37) -> 24570
A38: Infinity Story | B38: Кардиганы | C38: КОФТАДИОР/Шоколадный | D38: 824409755 | E38: 2044732970758 | F38: ONE SIZE | I38: 1 | J38: 1 | L38: 1 | N38: 2 | O38: 1 | Q38: 45 | R38: 1 | S38: 1 | U38: 2650 | V38: =SUM(G38:T38) -> 53 | W38: =IF(U38="","",U38*V38) -> 140450
A39: Infinity Story | B39: Костюмы | C39: КОСТВОЛНА/Шоколадный | D39: 848059668 | E39: 2043555813402 | F39: XS-M | G39: 2 | I39: 1 | Q39: 1 | V39: =SUM(G39:T39) -> 4 | W39: =IF(U39="","",U39*V39)
A40: Infinity Story | B40: Костюмы | C40: КОСТЖИЛЕТ/бежевый | D40: 824644290 | E40: 2036852563019 | F40: XS-M | Q40: 12 | U40: 1890 | V40: =SUM(G40:T40) -> 12 | W40: =IF(U40="","",U40*V40) -> 22680
...

Sheet Сверка
A1: Склад | B1: Дата акта | C1: Итого в исходном файле | D1: Итого в сводной | E1: Разница
A2: Электросталь | B2: 17.07 | C2: 84 | D2: =Сводная!G128 -> 84 | E2: =D2-C2 -> 0
A3: Краснодар | B3: 22.07 | C3: 29 | D3: =Сводная!H128 -> 29 | E3: =D3-C3 -> 0
A4: Невинномысск | B4: 22.07 | C4: 37 | D4: =Сводная!I128 -> 37 | E4: =D4-C4 -> 0
A5: Шушары | B5: 24.07 | C5: 43 | D5: =Сводная!J128 -> 43 | E5: =D5-C5 -> 0
A6: Рязань | B6: 29.07 | C6: 64 | D6: =Сводная!K128 -> 64 | E6: =D6-C6 -> 0
A7: Пенза | B7: 30.07 | C7: 6 | D7: =Сводная!L128 -> 6 | E7: =D7-C7 -> 0
A8: Сарапул | B8: 30.07 | C8: 22 | D8: =Сводная!M128 -> 22 | E8: =D8-C8 -> 0
A9: Волгоград | B9: 31.07 | C9: 6 | D9: =Сводная!N128 -> 6 | E9: =D9-C9 -> 0
A10: Новосемейкино Самара | B10: 02.08 | C10: 38 | D10: =Сводная!O128 -> 38 | E10: =D10-C10 -> 0
A11: Владимир | B11: 03.08 | C11: 43 | D11: =Сводная!P128 -> 43 | E11: =D11-C11 -> 0
A12: Тула | B12: 05.08 | C12: 1893 | D12: =Сводная!Q128 -> 1893 | E12: =D12-C12 -> 0
A13: ЕКБ Перспективная | B13: 07.08 | C13: 20 | D13: =Сводная!R128 -> 20 | E13: =D13-C13 -> 0
A14: Коледино | B14: 16.08 | C14: 27 | D14: =Сводная!S128 -> 27 | E14: =D14-C14 -> 0
A15: Котовск | B15: 26.08 | C15: 19 | D15: =Сводная!T128 -> 19 | E15: =D15-C15 -> 0
A16: ИТОГО | C16: =SUM(C2:C15) -> 2331 | D16: =SUM(D2:D15) -> 2331 | E16: =D16-C16 -> 0
A18: «Итого в исходном файле» — контрольная строка внизу каждого файла ВБ (введено вручную из файлов). Разница должна быть 0.
